<mujoco model="iiwa14">
  <compiler angle="radian" meshdir="assets" autolimits="true"/>

  <option integrator="implicitfast"/>

  <default>
    <default class="iiwa">
      <default class="visual">
        <geom type="mesh" contype="0" conaffinity="0" group="2" material="gray"/>
      </default>
      <default class="collision">
        <geom group="3"/>
      </default>
      <joint axis="0 0 1"/>
      <default class="joint1">
        <joint range="-2.96706 2.96706"/>
        <default class="joint2">
          <joint range="-2.0944 2.0944"/>
        </default>
      </default>
      <default class="joint3">
        <joint range="-3.05433 3.05433"/>
      </default>
    </default>

    <default class="2f85">
      <mesh scale="0.001 0.001 0.001"/>
      <general biastype="affine"/>

      <joint axis="0 0 1"/>
      <default class="driver">
        <joint range="0 0.9" armature="0.005" damping="0.1" solimplimit="0.95 0.99 0.001" solreflimit="0.005 1"/>
      </default>
      <default class="follower">
        <joint range="-0.872664 0.9" armature="0.001"  solimplimit="0.95 0.99 0.001" solreflimit="0.005 1"/>
      </default>
      <default class="spring_link">
        <joint range="-0.29670597283 0.9" armature="0.001" stiffness="0.05" springref="2.62" damping="0.00125"/>
      </default>
      <default class="coupler">
        <joint range="-1.57 0" armature="0.001" solimplimit="0.95 0.99 0.001" solreflimit="0.005 1"/>
      </default>

      <default class="2f85/visual">
        <geom type="mesh" contype="0" conaffinity="0" group="2" material="black"/>
      </default>
      <default class="2f85/collision">
        <geom type="mesh" group="3"/>
        <default class="pad_box1">
          <geom mass="1e-6" type="box" pos="0.043258  0 0.12"  size="0.002 0.011 0.009375" friction="0.7"
            solimp="0.95 0.99 0.001" solref="0.004 1" priority="1" rgba="0.55 0.55 0.55 1"/>
        </default>
        <default class="pad_box2">
          <geom mass="1e-6" type="box" pos="0.043258 0 0.13875" size="0.002 0.011 0.009375" friction="0.6"
            solimp="0.95 0.99 0.001" solref="0.004 1" priority="1" rgba="0.45 0.45 0.45 1"/>
        </default>
      </default>
    </default>
  </default>

  <asset>
    <material name="gray" rgba="0.4 0.4 0.4 1"/>
    <material name="light_gray" rgba="0.6 0.6 0.6 1"/>
    <material name="black" rgba="0 0 0 1"/>
    <material name="orange" rgba="1 0.423529 0.0392157 1"/>
    <material name="metal" rgba="0.58 0.58 0.58 1"/>
    <material name="silicone" rgba="0.1882 0.1882 0.1882 1"/>
    <material name="2f85/black" rgba="0.149 0.149 0.149 1"/>

    <mesh file="link_0.obj"/>
    <mesh file="link_1.obj"/>
    <mesh file="link_2_orange.obj"/>
    <mesh file="link_2_grey.obj"/>
    <mesh file="link_3.obj"/>
    <mesh file="band.obj"/>
    <mesh file="kuka.obj"/>
    <mesh file="link_4_orange.obj"/>
    <mesh file="link_4_grey.obj"/>
    <mesh file="link_5.obj"/>
    <mesh file="link_6_orange.obj"/>
    <mesh file="link_6_grey.obj"/>
    <mesh file="link_7.obj"/>

    <mesh file="base.stl"/>
    <mesh file="base_coupling.stl"/>
    <mesh file="c-a01-85-open.stl"/>
    <mesh file="driver.stl"/>
    <mesh file="coupler.stl"/>
    <mesh file="spring_link.stl"/>
    <mesh file="follower.stl"/>
    <mesh file="tongue.stl"/>
  </asset>

  <worldbody>
    <light name="top" pos="0 0 2" mode="trackcom"/>
    <body name="base" childclass="iiwa">
      <inertial mass="5" pos="-0.1 0 0.07" diaginertia="0.05 0.06 0.03"/>
      <geom class="visual" mesh="link_0"/>
      <geom class="collision" size="0.12" pos="0 0 0.03"/>
      <geom class="collision" size="0.08" pos="-0.08 0 0.103"/>
      <geom class="collision" size="0.08" pos="-0.08 0 0.04"/>
      <geom class="collision" size="0.1" pos="0 0 0.14"/>
      <body name="link1" pos="0 0 0.1575">
        <inertial mass="5.76" pos="0 -0.03 0.12" diaginertia="0.0333 0.033 0.0123"/>
        <joint name="joint1" class="joint1"/>
        <geom class="visual" mesh="link_1"/>
        <geom class="collision" size="0.08" pos="0 0 -0.0005"/>
        <geom class="collision" size="0.075" pos="0.01 -0.025 0.0425"/>
        <geom class="collision" size="0.075" pos="-0.01 -0.025 0.0425"/>
        <geom class="collision" size="0.07" pos="0.01 -0.045 0.1025"/>
        <geom class="collision" size="0.07" pos="-0.01 -0.045 0.1025"/>
        <body name="link2" pos="0 0 0.2025" quat="0 0 1 1">
          <inertial mass="6.35" pos="0.0003 0.059 0.042" diaginertia="0.0305 0.0304 0.011" quat="0 0 1 1"/>
          <joint name="joint2" class="joint2"/>
          <geom class="visual" material="orange" mesh="link_2_orange"/>
          <geom class="visual" mesh="link_2_grey"/>
          <geom class="collision" size="0.095" pos="0 0 -0.01"/>
          <geom class="collision" size="0.09" pos="0 0 0.045"/>
          <geom class="collision" size="0.07" pos="-0.01 0.04 0.054"/>
          <geom class="collision" size="0.065" pos="-0.01 0.09 0.04"/>
          <geom class="collision" size="0.065" pos="-0.01 0.13 0.02"/>
          <geom class="collision" size="0.07" pos="0.01 0.04 0.054"/>
          <geom class="collision" size="0.065" pos="0.01 0.09 0.04"/>
          <geom class="collision" size="0.065" pos="0.01 0.13 0.02"/>
          <geom class="collision" size="0.075" pos="0 0.18 0"/>
          <body name="link3" pos="0 0.2045 0" quat="0 0 1 1">
            <inertial mass="3.5" pos="0 0.03 0.13" diaginertia="0.025 0.0238 0.0076"/>
            <joint name="joint3" class="joint1"/>
            <geom class="visual" mesh="link_3"/>
            <geom class="visual" material="light_gray" mesh="band"/>
            <geom class="visual" material="black" mesh="kuka"/>
            <geom class="collision" size="0.075" pos="0 0 0.0355"/>
            <geom class="collision" size="0.06" pos="0.01 0.023 0.0855"/>
            <geom class="collision" size="0.055" pos="0.01 0.048 0.1255"/>
            <geom class="collision" size="0.06" pos="0.01 0.056 0.1755"/>
            <geom class="collision" size="0.06" pos="-0.01 0.023 0.0855"/>
            <geom class="collision" size="0.055" pos="-0.01 0.048 0.1255"/>
            <geom class="collision" size="0.06" pos="-0.01 0.056 0.1755"/>
            <geom class="collision" size="0.075" pos="0 0.045 0.2155"/>
            <geom class="collision" size="0.075" pos="0 0 0.2155"/>
            <body name="link4" pos="0 0 0.2155" quat="1 1 0 0">
              <inertial mass="3.5" pos="0 0.067 0.034" diaginertia="0.017 0.0164 0.006" quat="1 1 0 0"/>
              <joint name="joint4" class="joint2"/>
              <geom class="visual" material="orange" mesh="link_4_orange"/>
              <geom class="visual" mesh="link_4_grey"/>
              <geom class="collision" size="0.078" pos="0 0.01 0.046"/>
              <geom class="collision" size="0.06" pos="0.01 0.06 0.052"/>
              <geom class="collision" size="0.065" pos="0.01 0.12 0.034"/>
              <geom class="collision" size="0.06" pos="-0.01 0.06 0.052"/>
              <geom class="collision" size="0.065" pos="-0.01 0.12 0.034"/>
              <geom class="collision" size="0.075" pos="0 0.184 0"/>
              <body name="link5" pos="0 0.1845 0" quat="0 0 1 1">
                <inertial mass="3.5" pos="0.0001 0.021 0.076" diaginertia="0.01 0.0087 0.00449"/>
                <joint name="joint5" class="joint1"/>
                <geom class="visual" mesh="link_5"/>
                <geom class="visual" material="light_gray" mesh="band"/>
                <geom class="visual" material="black" mesh="kuka"/>
                <geom class="collision" size="0.075" pos="0 0 0.0335"/>
                <geom class="collision" size="0.05" pos="-0.012 0.031 0.0755"/>
                <geom class="collision" size="0.05" pos="0.012 0.031 0.0755"/>
                <geom class="collision" size="0.04" pos="-0.012 0.06 0.1155"/>
                <geom class="collision" size="0.04" pos="0.012 0.06 0.1155"/>
                <geom class="collision" size="0.04" pos="-0.01 0.065 0.1655"/>
                <geom class="collision" size="0.04" pos="0.01 0.065 0.1655"/>
                <geom class="collision" size="0.035" pos="-0.012 0.065 0.1855"/>
                <geom class="collision" size="0.035" pos="0.012 0.065 0.1855"/>
                <body name="link6" pos="0 0 0.2155" quat="1 1 0 0">
                  <inertial mass="1.8" pos="0 0.0006 0.0004" diaginertia="0.0049 0.0047 0.0036" quat="1 1 0 0"/>
                  <joint name="joint6" class="joint2"/>
                  <geom class="visual" material="orange" mesh="link_6_orange"/>
                  <geom class="visual" mesh="link_6_grey"/>
                  <geom class="collision" size="0.055" pos="0 0 -0.059"/>
                  <geom class="collision" size="0.065" pos="0 -0.03 0.011"/>
                  <geom class="collision" size="0.08"/>
                  <body name="link7" pos="0 0.081 0" quat="0 0 1 1">
                    <inertial mass="1.2" pos="0 0 0.02" diaginertia="0.001 0.001 0.001"/>
                    <joint name="joint7" class="joint3"/>
                    <geom class="visual" mesh="link_7"/>
                    <geom class="collision" size="0.06" pos="0 0 0.001"/>
                    <body name="attachment" pos="0 0 0.045" quat="0 0 0 1">
                      <site name="attachment_site" rgba="1 0 0 1" size="0.01" group="1"/>
                      <body name="base_mount" childclass="2f85">
                        <inertial mass="0.777441" pos="0 -2.70394e-05 0.0354675" quat="1 -0.00152849 0 0"
                          diaginertia="0.000260285 0.000225381 0.000152708"/>
                        <geom class="2f85/visual" pos="0 0 0.0108" quat="0 0 0 1"   mesh="base"/>
                        <geom class="2f85/visual" pos="0 0 0.004" quat="1 -1 0 0"   mesh="base_coupling"/>
                        <geom class="2f85/visual" pos="0 0 0.0108" quat="1 0 0 0"  material="metal" mesh="c-a01-85-open"/>
                        <geom class="2f85/collision" mesh="base"/>
                        <!-- Left-hand side 4-bar linkage -->
                        <body name="left_driver" pos="-0.0306011 0.00475 0.0657045" quat="1 -1 0 0">
                          <inertial mass="0.00899563" pos="0 0.0177547 0.00107314" quat="0.681301 0.732003 0 0"
                              diaginertia="1.72352e-06 1.60906e-06 3.22006e-07"/>
                          <joint name="left_driver_joint" class="driver"/>
                          <geom class="2f85/visual" pos="0.0306011 0.0549045 -0.0047" quat="1 1 0 0"  material="metal" mesh="driver"/>
                          <geom class="2f85/collision" pos="0.0306011 0.0549045 -0.0047" quat="1 1 0 0"   mesh="driver"/>
                          <body name="left_coupler" pos="-0.0314249 0.00453223 -0.0102" quat="0 0 0 1">
                            <inertial mass="0.0140974" pos="0 0.00301209 0.0232175" quat="0.705636 -0.0455904 0.0455904 0.705636"
                            diaginertia="4.16206e-06 3.52216e-06 8.88131e-07"/>
                            <geom class="2f85/visual" pos="-0.062026 -0.0503723 0.0055" quat="1 -1 0 0"   mesh="coupler"/>
                            <geom class="2f85/collision" pos="-0.062026 -0.0503723 0.0055" quat="1 -1 0 0"  mesh="coupler"/>
                          </body>
                        </body>
                        <body name="left_spring_link" pos="-0.0127 -0.012 0.07222" quat="1 -1 0 0">
                          <inertial mass="0.0221642" pos="-8.65005e-09 0.0181624 0.0212658" quat="0.663403 -0.244737 0.244737 0.663403"
                              diaginertia="8.96853e-06 6.71733e-06 2.63931e-06"/>
                          <joint name="left_spring_link_joint" class="spring_link"/>
                          <geom class="2f85/visual" pos="0.0127 0.06142 0.01205" quat="1 1 0 0" type="mesh"  mesh="spring_link"/>
                          <geom class="2f85/collision" pos="0.0127 0.06142 0.01205" quat="1 1 0 0" type="mesh"  mesh="spring_link"/>
                          <body name="left_follower" pos="-0.0382079 -0.0425003 0.00295" quat="0 -1 -1.90231e-05 0">
                            <inertial mass="0.0125222" pos="0 -0.011046 0.0124786" quat="1 0.1664 0 0"
                            diaginertia="2.67415e-06 2.4559e-06 6.02031e-07"/>
                            <joint name="left_follower" class="follower"/>
                            <geom class="2f85/visual" pos="0.0509079 -0.10392 -0.0091" quat="1 -1 0 0" type="mesh"  mesh="follower"/>
                            <geom class="2f85/visual" pos="0.0509079 -0.10392 -0.0091" quat="1 -1 0 0" type="mesh" material="metal" mesh="tongue"/>
                            <geom class="2f85/collision" pos="0.0509079 -0.10392 -0.0091" quat="1 -1 0 0" type="mesh"  mesh="follower"/>
                            <geom class="2f85/collision" pos="0.0509079 -0.10392 -0.0091" quat="1 -1 0 0" type="mesh"  mesh="tongue"/>
                            <body name="left_pad" pos="-0.0377897 -0.103916 -0.0091" quat="1 -1 0 0" >
                              <geom class="pad_box1" name="left_pad1"/>
                              <geom class="pad_box2" name="left_pad2"/>
                            </body>
                          </body>
                        </body>
                        <!-- Right-hand side 4-bar linkage -->
                        <body name="right_driver" pos="0.0306011 -0.00475 0.0657045" quat="0 0 -1 1">
                          <inertial mass="0.00899563" pos="2.96931e-12 0.0177547 0.00107314" quat="0.681301 0.732003 0 0"
                          diaginertia="1.72352e-06 1.60906e-06 3.22006e-07"/>
                          <joint name="right_driver_joint" class="driver"/>
                          <geom class="2f85/visual" pos="0.0306011 0.0549045 -0.0047" quat="1 1 0 0" material="metal" mesh="driver"/>
                          <geom class="2f85/collision" pos="0.0306011 0.0549045 -0.0047" quat="1 1 0 0"  mesh="driver"/>
                          <body name="right_coupler" pos="-0.0314249 0.00453223 -0.0102" quat="0 0 0 1">
                            <inertial mass="0.0140974" pos="0 0.00301209 0.0232175" quat="0.705636 -0.0455904 0.0455904 0.705636"
                            diaginertia="4.16206e-06 3.52216e-06 8.88131e-07"/>
                            <geom class="2f85/visual" pos="-0.062026 -0.0503723 0.0055" quat="1 -1 0 0"   mesh="coupler"/>
                            <geom class="2f85/collision" pos="-0.062026 -0.0503723 0.0055" quat="1 -1 0 0"   mesh="coupler"/>
                          </body>
                        </body>
                        <body name="right_spring_link" pos="0.0127 0.012 0.07222" quat="0 0 -1 1">
                          <inertial mass="0.0221642" pos="-8.65005e-09 0.0181624 0.0212658" quat="0.663403 -0.244737 0.244737 0.663403"
                          diaginertia="8.96853e-06 6.71733e-06 2.63931e-06"/>
                          <joint name="right_spring_link_joint" class="spring_link"/>
                          <geom class="2f85/visual" pos="0.0127 0.06142 0.01205" quat="1 1 0 0"   mesh="spring_link"/>
                          <geom class="2f85/collision" pos="0.0127 0.06142 0.01205" quat="1 1 0 0"   mesh="spring_link"/>
                          <body name="right_follower" pos="-0.0382079 -0.0425003 0.00295" quat="0 -1 0 0">
                            <inertial mass="0.0125222" pos="0 -0.011046 0.0124786" quat="1 0.1664 0 0"
                            diaginertia="2.67415e-06 2.4559e-06 6.02031e-07"/>
                            <joint name="right_follower_joint" class="follower"/>
                            <geom class="2f85/visual" pos="0.0509079 -0.10392 -0.0091" quat="1 -1 0 0"  material="metal" mesh="tongue"/>
                            <geom class="2f85/visual" pos="0.0509079 -0.10392 -0.0091" quat="1 -1 0 0"   mesh="follower"/>
                            <geom class="2f85/collision" pos="0.0509079 -0.10392 -0.0091" quat="1 -1 0 0"   mesh="tongue"/>
                            <geom class="2f85/collision" pos="0.0509079 -0.10392 -0.0091" quat="1 -1 0 0"   mesh="follower"/>
                            <body name="right_pad" pos="-0.0377897 -0.103916 -0.0091"   quat="1 -1 0 0" >
                              <geom class="pad_box1" name="right_pad1"/>
                              <geom class="pad_box2" name="right_pad2"/>
                            </body>
                          </body>
                        </body>
                      </body>

                    </body>
                  </body>
                </body>
              </body>
            </body>
          </body>
        </body>
      </body>
    </body>
  </worldbody>

  <contact>
    <exclude body1="base" body2="link1"/>
    <exclude body1="base" body2="link2"/>
    <exclude body1="base" body2="link3"/>
    <exclude body1="link1" body2="link3"/>
    <exclude body1="link3" body2="link5"/>
    <exclude body1="link4" body2="link7"/>
    <exclude body1="link5" body2="link7"/>

    <exclude body1="base_mount" body2="left_driver"/>
    <exclude body1="base_mount" body2="right_driver"/>
    <exclude body1="base_mount" body2="left_spring_link"/>
    <exclude body1="base_mount" body2="right_spring_link"/>
    <exclude body1="right_coupler" body2="right_follower"/>
    <exclude body1="left_coupler" body2="left_follower"/>

  </contact>


  <!--
    This adds stability to the model by having a tendon that distributes the forces between both
    joints, such that the equality constraint doesn't have to do that much work in order to equalize
    both joints. Since both joints share the same sign, we split the force between both equally by
    setting coef=0.485
  -->
  <tendon>
    <fixed name="split">
      <joint joint="right_driver_joint" coef="0.485"/>
      <joint joint="left_driver_joint" coef="0.485"/>
    </fixed>
  </tendon>

  <equality>
    <connect anchor="-0.0179014 -0.00651468 0.0044" body1="right_follower" body2="right_coupler" solimp="0.95 0.99 0.001" solref="0.005 1"/>
    <connect anchor="-0.0179014 -0.00651468 0.0044" body1="left_follower" body2="left_coupler" solimp="0.95 0.99 0.001" solref="0.005 1"/>
    <joint joint1="right_driver_joint" joint2="left_driver_joint" polycoef="0 1 0 0 0" solimp="0.95 0.99 0.001"
    solref="0.005 1"/>
  </equality>


  <actuator>
    <motor name="joint1" joint="joint1" ctrlrange="-320 320"/>
    <motor name="joint2" joint="joint2" ctrlrange="-320 320"/>
    <motor name="joint3" joint="joint3" ctrlrange="-176 176"/>
    <motor name="joint4" joint="joint4" ctrlrange="-176 176"/>
    <motor name="joint5" joint="joint5" ctrlrange="-110 110"/>
    <motor name="joint6" joint="joint6" ctrlrange="-40 40"/>
    <motor name="joint7" joint="joint7" ctrlrange="-40 40"/>
    <general class="2f85" name="fingers_actuator" tendon="split" forcerange="-5 5" ctrlrange="0 255"
      gainprm="0.3137255 0 0" biasprm="0 -100 -10"/>
  </actuator>

  <keyframe>
    <key name="home" qpos="0 0 0 -1.5708 0 1.5708 0 0.002 0.002 0.002 0.002 0.002 0.002 0.5 0.5 0.025 0 0 1 0"/>
  </keyframe>
</mujoco>
